{
 "cells": [
  {
   "cell_type": "code",
   "execution_count": 1,
   "metadata": {},
   "outputs": [],
   "source": [
    "import tensorflow as tf\n",
    "# from keras.backend.tensorflow_backend import set_session\n",
    "config = tf.ConfigProto()\n",
    "config.gpu_options.per_process_gpu_memory_fraction = 0.9 # 使⽤45%記憶體\n",
    "# set_session(tf.Session()) "
   ]
  },
  {
   "cell_type": "code",
   "execution_count": 2,
   "metadata": {},
   "outputs": [
    {
     "name": "stdout",
     "output_type": "stream",
     "text": [
      "66787 16697\n"
     ]
    }
   ],
   "source": [
    "import numpy as np\n",
    "from os import listdir\n",
    "from random import shuffle\n",
    "from PIL import Image\n",
    "\n",
    "\n",
    "image_path = [\"../DeepLearning/kermany2018/NewSize/train/CNV\", \n",
    "              \"../DeepLearning/kermany2018/NewSize/train/DME\",\n",
    "              \"../DeepLearning/kermany2018/NewSize/train/DRUSEN\",\n",
    "              \"../DeepLearning/kermany2018/NewSize/train/NORMAL\"]\n",
    "#image_path = [\"./data/A\", \"./data/B\"]\n",
    "\n",
    "def preprocess_to_data_file(data_dir_list, ratio=0.8):\n",
    "\n",
    "    total_list = [] \n",
    "   \n",
    "    '''\n",
    "        create all images into (image path, label) format and write to total_data.txt \n",
    "    ''' \n",
    "    with open('total_data.txt', 'w') as f:\n",
    "        for index, data_dir in enumerate(data_dir_list):\n",
    "            for filename in listdir(data_dir):\n",
    "                #print(\"{} {}\".format(data_dir_list[index]+'/'+filename, index))\n",
    "                f.write('{} {}\\n'.format(data_dir_list[index]+'/'+filename.replace(' ',''), index))\n",
    "                total_list.append(data_dir_list[index]+'/'+filename.replace(' ','')+' '+str(index))\n",
    "\n",
    "    #print(total_list)\n",
    "    '''\n",
    "        shuffle total_list\n",
    "    ''' \n",
    "    shuffle(total_list)\n",
    "\n",
    "    '''\n",
    "        split total_list to train_list and test_list. \n",
    "        write train_list/test_list into train_data.txt/test_data.txt\n",
    "    ''' \n",
    "    train_list = total_list[:int(ratio*len(total_list))]\n",
    "    test_list = total_list[int(ratio*len(total_list)):]\n",
    "    print(len(train_list),len(test_list))\n",
    "\n",
    "    with open('train_data.txt', 'w') as f:\n",
    "        for i in train_list:\n",
    "            f.write(i+'\\n')\n",
    "\n",
    "    with open('test_data.txt', 'w') as f:\n",
    "        for i in test_list:\n",
    "            f.write(i+'\\n')\n",
    "\n",
    "\n",
    "\n",
    "preprocess_to_data_file(image_path, 0.8)\n"
   ]
  },
  {
   "cell_type": "code",
   "execution_count": 3,
   "metadata": {},
   "outputs": [
    {
     "name": "stdout",
     "output_type": "stream",
     "text": [
      "loading image path......\n",
      "number of train image is 66787\n",
      "number of test image is 16697\n",
      "start training......\n",
      "step=0, loss=51.532569885253906, accuracy=0.125\n",
      "test accuracy = 0.4555000066757202\n"
     ]
    }
   ],
   "source": [
    "import numpy as np\n",
    "from random import shuffle\n",
    "from PIL import Image\n",
    "import tensorflow as tf\n",
    "import os\n",
    "tf.reset_default_graph()\n",
    "\n",
    "def one_hot_encoding(label):\n",
    "\n",
    "    '''\n",
    "    change label id to one-hot encoding\n",
    "    '''\n",
    "\n",
    "    values = np.asarray(label)\n",
    "    n_class = 4\n",
    "    encoding_result = np.eye(n_class)[values]\n",
    "    return encoding_result \n",
    "\n",
    "\n",
    "\n",
    "def load_data(file_path):\n",
    "\n",
    "    '''\n",
    "    load all of training data\n",
    "    '''\n",
    "\n",
    "    with open(file_path, \"r\") as lines:\n",
    "        data_list = []\n",
    "        for line in lines:\n",
    "            data_list.append(line.replace('\\n',''))\n",
    "\n",
    "        shuffle(data_list) \n",
    "\n",
    "    data_path = []\n",
    "    data_label = []\n",
    "    for data in data_list:\n",
    "        data_path.append(data.split(' ')[0])\n",
    "        data_label.append(int(data.split(' ')[1]))\n",
    "\n",
    "    return data_path, data_label\n",
    "\n",
    "\n",
    "def load_batch_data(data_path, labels):\n",
    "    \n",
    "\n",
    "    batch_data = []\n",
    "    for index, im in enumerate(data_path): \n",
    "        raw_image = Image.open(im)\n",
    "        ### please notice this line if image have already been normalized \n",
    "        resize_image = raw_image.resize((80, 80))\n",
    "        normalized_image = np.asarray(resize_image)/255.0\n",
    "        normalized_image = normalized_image.reshape(80,80,1)\n",
    "        batch_data.append(normalized_image)\n",
    "\n",
    "    batch_label = one_hot_encoding(labels)\n",
    "\n",
    "\n",
    "    batch_data = np.asarray(batch_data, np.float32)\n",
    "    batch_label = np.asarray(batch_label, np.float32)\n",
    "    return batch_data, batch_label\n",
    "\n",
    "\n",
    "\n",
    "print('loading image path......')\n",
    "train_data, train_label = load_data(\"train_data.txt\")\n",
    "test_data, test_label = load_data(\"test_data.txt\")\n",
    "\n",
    "\n",
    "print('number of train image is {}'.format(len(train_data)))\n",
    "print('number of test image is {}'.format(len(test_data)))\n",
    "\n",
    "\n",
    "'''\n",
    "set network parameters \n",
    "\n",
    "'''\n",
    "# 162*212\n",
    "image_size_width = 80\n",
    "image_size_height = 80\n",
    "num_labels = 4 # 4種\n",
    "num_channels = 1 # 黑白\n",
    "batch_size = 256\n",
    "kernel_size = 3\n",
    "num_steps = 15\n",
    "\n",
    "'''\n",
    "create CNN model\n",
    "'''\n",
    "\n",
    "x = tf.placeholder(tf.float32, [None, image_size_height, image_size_width, num_channels],name='x')\n",
    "y = tf.placeholder(tf.float32, [None, num_labels],name='y')\n",
    "\n",
    "# initial variables\n",
    "layer1_weights = tf.Variable(tf.truncated_normal([kernel_size, kernel_size, num_channels, 32], stddev=0.1))\n",
    "layer1_biases = tf.Variable(tf.zeros([32]))\n",
    "layer2_weights = tf.Variable(tf.truncated_normal([kernel_size, kernel_size, 32, 64], stddev=0.1))\n",
    "layer2_biases = tf.Variable(tf.constant(1.0, shape=[64]))\n",
    "layer3_weights = tf.Variable(tf.truncated_normal([kernel_size, kernel_size, 64, 128], stddev=0.1))\n",
    "layer3_biases = tf.Variable(tf.constant(1.0, shape=[128]))\n",
    "\n",
    "layer4_weights = tf.Variable(tf.truncated_normal([12800, 1024], stddev=0.1))\n",
    "layer4_biases = tf.Variable(tf.constant(1.0, shape=[1024]))\n",
    "layer5_weights = tf.Variable(tf.truncated_normal([1024, num_labels], stddev=0.1))\n",
    "layer5_biases = tf.Variable(tf.constant(1.0, shape=[num_labels]))\n",
    "\n",
    "# CNN model detail\n",
    "def model(input_image):\n",
    "    conv1 = tf.nn.conv2d(input_image, layer1_weights, [1, 2, 2, 1], padding='SAME')\n",
    "    hidden1 = tf.nn.relu(conv1 + layer1_biases)\n",
    "    pool1 = tf.nn.max_pool(hidden1, ksize=[1, 2, 2, 1], strides=[1, 2, 2, 1], padding='SAME')\n",
    "\n",
    "    conv2 = tf.nn.conv2d(hidden1, layer2_weights, [1, 2, 2, 1], padding='SAME')\n",
    "    hidden2 = tf.nn.relu(conv2 + layer2_biases)\n",
    "    pool2 = tf.nn.max_pool(hidden2, ksize=[1, 2, 2, 1], strides=[1, 2, 2, 1], padding='SAME')\n",
    "    conv3 = tf.nn.conv2d(hidden2, layer3_weights, [1, 2, 2, 1], padding='SAME')\n",
    "    hidden3 = tf.nn.relu(conv3 + layer3_biases)\n",
    "    shape = hidden3.get_shape().as_list()\n",
    "\n",
    "    reshape = tf.reshape(hidden3, [-1, shape[1] * shape[2] * shape[3]])\n",
    "\n",
    "    hidden = tf.nn.relu(tf.matmul(reshape, layer4_weights) + layer4_biases)\n",
    "    \n",
    "    return tf.add(tf.matmul(hidden, layer5_weights),layer5_biases,name=\"logis\")\n",
    "\n",
    "# build model\n",
    "logits = model(x)\n",
    "\n",
    "# define cost\n",
    "loss = tf.reduce_mean(tf.nn.softmax_cross_entropy_with_logits_v2(labels=y, logits=logits))\n",
    "\n",
    "# optimization\n",
    "optimizer = tf.train.AdamOptimizer(1e-4).minimize(loss)\n",
    "# show prediction result\n",
    "prediction = tf.equal(tf.argmax(logits, 1), tf.argmax(y, 1))\n",
    "accuracy = tf.reduce_mean(tf.cast(prediction, tf.float32))\n",
    "\n",
    "saver = tf.train.Saver()\n",
    "\n",
    "with tf.Session(config=config) as sess:\n",
    "    sess.run(tf.global_variables_initializer())\n",
    "    print('start training......')\n",
    "    for step in range(num_steps):\n",
    "        offset = (step * batch_size) % (len(train_data) - batch_size)\n",
    "        batch_data_path = train_data[offset:(offset + batch_size)]\n",
    "        batch_label_path = train_label[offset:(offset + batch_size)]\n",
    "\n",
    "        train_batch_data, train_batch_labels = load_batch_data(batch_data_path, batch_label_path)\n",
    "\n",
    "\n",
    "        feed_dict = { x: train_batch_data, y: train_batch_labels}\n",
    "        _, l, train_accuracy_ = sess.run([optimizer, loss, accuracy], feed_dict=feed_dict)\n",
    "\n",
    "\n",
    "        if (step % 5 == 0):\n",
    "            saver.save(sess, \"train_model/model.ckpt\")\n",
    "            print('step={}, loss={}, accuracy={}'.format(step, l, train_accuracy_))\n",
    "            test_batch_data, test_batch_labels = load_batch_data(test_data[:2000], test_label[:2000])\n",
    "            feed_dict = { x: test_batch_data, y: test_batch_labels}\n",
    "            test_accuracy_ = sess.run(accuracy, feed_dict=feed_dict)\n",
    "            print('test accuracy = {}'.format(test_accuracy_))\n",
    "    \n",
    "    #print('start testing......')"
   ]
  },
  {
   "cell_type": "code",
   "execution_count": null,
   "metadata": {},
   "outputs": [],
   "source": [
    "# def load_batch_data(data_path):\n",
    "    \n",
    "\n",
    "#     batch_data = []\n",
    "#     for index, im in enumerate(data_path): \n",
    "raw_image = Image.open('kermany2018/NewSize/test/CNV/CNV-53018-1.jpeg')\n",
    "### please notice this line if image have already been normalized \n",
    "resize_image = raw_image.resize((80, 80))\n",
    "normalized_image = np.asarray(resize_image)/255.0\n",
    "normalized_image = normalized_image.reshape(80,80,1)\n",
    "#         batch_data.append(normalized_image)\n",
    "\n",
    "#     batch_label = one_hot_encoding(labels)\n",
    "\n",
    "\n",
    "batch_data = np.asarray(normalized_image, np.float32)\n",
    "batch_data=batch_data.reshape(1,80,80,1)\n",
    "#     batch_label = np.asarray(batch_label, np.float32)\n",
    "#         return batch_data\n",
    "print(batch_data.shape)"
   ]
  },
  {
   "cell_type": "code",
   "execution_count": 49,
   "metadata": {},
   "outputs": [],
   "source": []
  },
  {
   "cell_type": "code",
   "execution_count": 52,
   "metadata": {},
   "outputs": [
    {
     "name": "stdout",
     "output_type": "stream",
     "text": [
      "INFO:tensorflow:Restoring parameters from train_model/model.ckpt\n"
     ]
    },
    {
     "ename": "InvalidArgumentError",
     "evalue": "Restoring from checkpoint failed. This is most likely due to a mismatch between the current graph and the graph from the checkpoint. Please ensure that you have not altered the graph expected based on the checkpoint. Original error:\n\nAssign requires shapes of both tensors to match. lhs shape= [3,3,64,128] rhs shape= [6400,1024]\n\t [[Node: save/Assign_14 = Assign[T=DT_FLOAT, _class=[\"loc:@Variable_4\"], use_locking=true, validate_shape=true, _device=\"/job:localhost/replica:0/task:0/device:GPU:0\"](Variable_4/Adam_1, save/RestoreV2/_29)]]\n\nCaused by op 'save/Assign_14', defined at:\n  File \"/opt/intel/intelpython3/lib/python3.6/runpy.py\", line 193, in _run_module_as_main\n    \"__main__\", mod_spec)\n  File \"/opt/intel/intelpython3/lib/python3.6/runpy.py\", line 85, in _run_code\n    exec(code, run_globals)\n  File \"/opt/intel/intelpython3/lib/python3.6/site-packages/ipykernel_launcher.py\", line 16, in <module>\n    app.launch_new_instance()\n  File \"/opt/intel/intelpython3/lib/python3.6/site-packages/traitlets/config/application.py\", line 658, in launch_instance\n    app.start()\n  File \"/opt/intel/intelpython3/lib/python3.6/site-packages/ipykernel/kernelapp.py\", line 497, in start\n    self.io_loop.start()\n  File \"/opt/intel/intelpython3/lib/python3.6/site-packages/tornado/platform/asyncio.py\", line 132, in start\n    self.asyncio_loop.run_forever()\n  File \"/opt/intel/intelpython3/lib/python3.6/asyncio/base_events.py\", line 421, in run_forever\n    self._run_once()\n  File \"/opt/intel/intelpython3/lib/python3.6/asyncio/base_events.py\", line 1426, in _run_once\n    handle._run()\n  File \"/opt/intel/intelpython3/lib/python3.6/asyncio/events.py\", line 127, in _run\n    self._callback(*self._args)\n  File \"/opt/intel/intelpython3/lib/python3.6/site-packages/tornado/platform/asyncio.py\", line 122, in _handle_events\n    handler_func(fileobj, events)\n  File \"/opt/intel/intelpython3/lib/python3.6/site-packages/tornado/stack_context.py\", line 300, in null_wrapper\n    return fn(*args, **kwargs)\n  File \"/opt/intel/intelpython3/lib/python3.6/site-packages/zmq/eventloop/zmqstream.py\", line 450, in _handle_events\n    self._handle_recv()\n  File \"/opt/intel/intelpython3/lib/python3.6/site-packages/zmq/eventloop/zmqstream.py\", line 480, in _handle_recv\n    self._run_callback(callback, msg)\n  File \"/opt/intel/intelpython3/lib/python3.6/site-packages/zmq/eventloop/zmqstream.py\", line 432, in _run_callback\n    callback(*args, **kwargs)\n  File \"/opt/intel/intelpython3/lib/python3.6/site-packages/tornado/stack_context.py\", line 300, in null_wrapper\n    return fn(*args, **kwargs)\n  File \"/opt/intel/intelpython3/lib/python3.6/site-packages/ipykernel/kernelbase.py\", line 283, in dispatcher\n    return self.dispatch_shell(stream, msg)\n  File \"/opt/intel/intelpython3/lib/python3.6/site-packages/ipykernel/kernelbase.py\", line 233, in dispatch_shell\n    handler(stream, idents, msg)\n  File \"/opt/intel/intelpython3/lib/python3.6/site-packages/ipykernel/kernelbase.py\", line 399, in execute_request\n    user_expressions, allow_stdin)\n  File \"/opt/intel/intelpython3/lib/python3.6/site-packages/ipykernel/ipkernel.py\", line 208, in do_execute\n    res = shell.run_cell(code, store_history=store_history, silent=silent)\n  File \"/opt/intel/intelpython3/lib/python3.6/site-packages/ipykernel/zmqshell.py\", line 537, in run_cell\n    return super(ZMQInteractiveShell, self).run_cell(*args, **kwargs)\n  File \"/opt/intel/intelpython3/lib/python3.6/site-packages/IPython/core/interactiveshell.py\", line 2662, in run_cell\n    raw_cell, store_history, silent, shell_futures)\n  File \"/opt/intel/intelpython3/lib/python3.6/site-packages/IPython/core/interactiveshell.py\", line 2785, in _run_cell\n    interactivity=interactivity, compiler=compiler, result=result)\n  File \"/opt/intel/intelpython3/lib/python3.6/site-packages/IPython/core/interactiveshell.py\", line 2901, in run_ast_nodes\n    if self.run_code(code, result):\n  File \"/opt/intel/intelpython3/lib/python3.6/site-packages/IPython/core/interactiveshell.py\", line 2961, in run_code\n    exec(code_obj, self.user_global_ns, self.user_ns)\n  File \"<ipython-input-52-279c9ac013b5>\", line 63, in <module>\n    saver = tf.train.Saver()\n  File \"/opt/intel/intelpython3/lib/python3.6/site-packages/tensorflow/python/training/saver.py\", line 1281, in __init__\n    self.build()\n  File \"/opt/intel/intelpython3/lib/python3.6/site-packages/tensorflow/python/training/saver.py\", line 1293, in build\n    self._build(self._filename, build_save=True, build_restore=True)\n  File \"/opt/intel/intelpython3/lib/python3.6/site-packages/tensorflow/python/training/saver.py\", line 1330, in _build\n    build_save=build_save, build_restore=build_restore)\n  File \"/opt/intel/intelpython3/lib/python3.6/site-packages/tensorflow/python/training/saver.py\", line 778, in _build_internal\n    restore_sequentially, reshape)\n  File \"/opt/intel/intelpython3/lib/python3.6/site-packages/tensorflow/python/training/saver.py\", line 419, in _AddRestoreOps\n    assign_ops.append(saveable.restore(saveable_tensors, shapes))\n  File \"/opt/intel/intelpython3/lib/python3.6/site-packages/tensorflow/python/training/saver.py\", line 112, in restore\n    self.op.get_shape().is_fully_defined())\n  File \"/opt/intel/intelpython3/lib/python3.6/site-packages/tensorflow/python/ops/state_ops.py\", line 216, in assign\n    validate_shape=validate_shape)\n  File \"/opt/intel/intelpython3/lib/python3.6/site-packages/tensorflow/python/ops/gen_state_ops.py\", line 60, in assign\n    use_locking=use_locking, name=name)\n  File \"/opt/intel/intelpython3/lib/python3.6/site-packages/tensorflow/python/framework/op_def_library.py\", line 787, in _apply_op_helper\n    op_def=op_def)\n  File \"/opt/intel/intelpython3/lib/python3.6/site-packages/tensorflow/python/util/deprecation.py\", line 454, in new_func\n    return func(*args, **kwargs)\n  File \"/opt/intel/intelpython3/lib/python3.6/site-packages/tensorflow/python/framework/ops.py\", line 3155, in create_op\n    op_def=op_def)\n  File \"/opt/intel/intelpython3/lib/python3.6/site-packages/tensorflow/python/framework/ops.py\", line 1717, in __init__\n    self._traceback = tf_stack.extract_stack()\n\nInvalidArgumentError (see above for traceback): Restoring from checkpoint failed. This is most likely due to a mismatch between the current graph and the graph from the checkpoint. Please ensure that you have not altered the graph expected based on the checkpoint. Original error:\n\nAssign requires shapes of both tensors to match. lhs shape= [3,3,64,128] rhs shape= [6400,1024]\n\t [[Node: save/Assign_14 = Assign[T=DT_FLOAT, _class=[\"loc:@Variable_4\"], use_locking=true, validate_shape=true, _device=\"/job:localhost/replica:0/task:0/device:GPU:0\"](Variable_4/Adam_1, save/RestoreV2/_29)]]\n",
     "output_type": "error",
     "traceback": [
      "\u001b[0;31m---------------------------------------------------------------------------\u001b[0m",
      "\u001b[0;31mInvalidArgumentError\u001b[0m                      Traceback (most recent call last)",
      "\u001b[0;32m/opt/intel/intelpython3/lib/python3.6/site-packages/tensorflow/python/client/session.py\u001b[0m in \u001b[0;36m_do_call\u001b[0;34m(self, fn, *args)\u001b[0m\n\u001b[1;32m   1277\u001b[0m     \u001b[0;32mtry\u001b[0m\u001b[0;34m:\u001b[0m\u001b[0;34m\u001b[0m\u001b[0m\n\u001b[0;32m-> 1278\u001b[0;31m       \u001b[0;32mreturn\u001b[0m \u001b[0mfn\u001b[0m\u001b[0;34m(\u001b[0m\u001b[0;34m*\u001b[0m\u001b[0margs\u001b[0m\u001b[0;34m)\u001b[0m\u001b[0;34m\u001b[0m\u001b[0m\n\u001b[0m\u001b[1;32m   1279\u001b[0m     \u001b[0;32mexcept\u001b[0m \u001b[0merrors\u001b[0m\u001b[0;34m.\u001b[0m\u001b[0mOpError\u001b[0m \u001b[0;32mas\u001b[0m \u001b[0me\u001b[0m\u001b[0;34m:\u001b[0m\u001b[0;34m\u001b[0m\u001b[0m\n",
      "\u001b[0;32m/opt/intel/intelpython3/lib/python3.6/site-packages/tensorflow/python/client/session.py\u001b[0m in \u001b[0;36m_run_fn\u001b[0;34m(feed_dict, fetch_list, target_list, options, run_metadata)\u001b[0m\n\u001b[1;32m   1262\u001b[0m       return self._call_tf_sessionrun(\n\u001b[0;32m-> 1263\u001b[0;31m           options, feed_dict, fetch_list, target_list, run_metadata)\n\u001b[0m\u001b[1;32m   1264\u001b[0m \u001b[0;34m\u001b[0m\u001b[0m\n",
      "\u001b[0;32m/opt/intel/intelpython3/lib/python3.6/site-packages/tensorflow/python/client/session.py\u001b[0m in \u001b[0;36m_call_tf_sessionrun\u001b[0;34m(self, options, feed_dict, fetch_list, target_list, run_metadata)\u001b[0m\n\u001b[1;32m   1349\u001b[0m         \u001b[0mself\u001b[0m\u001b[0;34m.\u001b[0m\u001b[0m_session\u001b[0m\u001b[0;34m,\u001b[0m \u001b[0moptions\u001b[0m\u001b[0;34m,\u001b[0m \u001b[0mfeed_dict\u001b[0m\u001b[0;34m,\u001b[0m \u001b[0mfetch_list\u001b[0m\u001b[0;34m,\u001b[0m \u001b[0mtarget_list\u001b[0m\u001b[0;34m,\u001b[0m\u001b[0;34m\u001b[0m\u001b[0m\n\u001b[0;32m-> 1350\u001b[0;31m         run_metadata)\n\u001b[0m\u001b[1;32m   1351\u001b[0m \u001b[0;34m\u001b[0m\u001b[0m\n",
      "\u001b[0;31mInvalidArgumentError\u001b[0m: Assign requires shapes of both tensors to match. lhs shape= [3,3,64,128] rhs shape= [6400,1024]\n\t [[Node: save/Assign_14 = Assign[T=DT_FLOAT, _class=[\"loc:@Variable_4\"], use_locking=true, validate_shape=true, _device=\"/job:localhost/replica:0/task:0/device:GPU:0\"](Variable_4/Adam_1, save/RestoreV2/_29)]]",
      "\nDuring handling of the above exception, another exception occurred:\n",
      "\u001b[0;31mInvalidArgumentError\u001b[0m                      Traceback (most recent call last)",
      "\u001b[0;32m/opt/intel/intelpython3/lib/python3.6/site-packages/tensorflow/python/training/saver.py\u001b[0m in \u001b[0;36mrestore\u001b[0;34m(self, sess, save_path)\u001b[0m\n\u001b[1;32m   1724\u001b[0m         sess.run(self.saver_def.restore_op_name,\n\u001b[0;32m-> 1725\u001b[0;31m                  {self.saver_def.filename_tensor_name: save_path})\n\u001b[0m\u001b[1;32m   1726\u001b[0m     \u001b[0;32mexcept\u001b[0m \u001b[0merrors\u001b[0m\u001b[0;34m.\u001b[0m\u001b[0mNotFoundError\u001b[0m \u001b[0;32mas\u001b[0m \u001b[0merr\u001b[0m\u001b[0;34m:\u001b[0m\u001b[0;34m\u001b[0m\u001b[0m\n",
      "\u001b[0;32m/opt/intel/intelpython3/lib/python3.6/site-packages/tensorflow/python/client/session.py\u001b[0m in \u001b[0;36mrun\u001b[0;34m(self, fetches, feed_dict, options, run_metadata)\u001b[0m\n\u001b[1;32m    876\u001b[0m       result = self._run(None, fetches, feed_dict, options_ptr,\n\u001b[0;32m--> 877\u001b[0;31m                          run_metadata_ptr)\n\u001b[0m\u001b[1;32m    878\u001b[0m       \u001b[0;32mif\u001b[0m \u001b[0mrun_metadata\u001b[0m\u001b[0;34m:\u001b[0m\u001b[0;34m\u001b[0m\u001b[0m\n",
      "\u001b[0;32m/opt/intel/intelpython3/lib/python3.6/site-packages/tensorflow/python/client/session.py\u001b[0m in \u001b[0;36m_run\u001b[0;34m(self, handle, fetches, feed_dict, options, run_metadata)\u001b[0m\n\u001b[1;32m   1099\u001b[0m       results = self._do_run(handle, final_targets, final_fetches,\n\u001b[0;32m-> 1100\u001b[0;31m                              feed_dict_tensor, options, run_metadata)\n\u001b[0m\u001b[1;32m   1101\u001b[0m     \u001b[0;32melse\u001b[0m\u001b[0;34m:\u001b[0m\u001b[0;34m\u001b[0m\u001b[0m\n",
      "\u001b[0;32m/opt/intel/intelpython3/lib/python3.6/site-packages/tensorflow/python/client/session.py\u001b[0m in \u001b[0;36m_do_run\u001b[0;34m(self, handle, target_list, fetch_list, feed_dict, options, run_metadata)\u001b[0m\n\u001b[1;32m   1271\u001b[0m       return self._do_call(_run_fn, feeds, fetches, targets, options,\n\u001b[0;32m-> 1272\u001b[0;31m                            run_metadata)\n\u001b[0m\u001b[1;32m   1273\u001b[0m     \u001b[0;32melse\u001b[0m\u001b[0;34m:\u001b[0m\u001b[0;34m\u001b[0m\u001b[0m\n",
      "\u001b[0;32m/opt/intel/intelpython3/lib/python3.6/site-packages/tensorflow/python/client/session.py\u001b[0m in \u001b[0;36m_do_call\u001b[0;34m(self, fn, *args)\u001b[0m\n\u001b[1;32m   1290\u001b[0m           \u001b[0;32mpass\u001b[0m\u001b[0;34m\u001b[0m\u001b[0m\n\u001b[0;32m-> 1291\u001b[0;31m       \u001b[0;32mraise\u001b[0m \u001b[0mtype\u001b[0m\u001b[0;34m(\u001b[0m\u001b[0me\u001b[0m\u001b[0;34m)\u001b[0m\u001b[0;34m(\u001b[0m\u001b[0mnode_def\u001b[0m\u001b[0;34m,\u001b[0m \u001b[0mop\u001b[0m\u001b[0;34m,\u001b[0m \u001b[0mmessage\u001b[0m\u001b[0;34m)\u001b[0m\u001b[0;34m\u001b[0m\u001b[0m\n\u001b[0m\u001b[1;32m   1292\u001b[0m \u001b[0;34m\u001b[0m\u001b[0m\n",
      "\u001b[0;31mInvalidArgumentError\u001b[0m: Assign requires shapes of both tensors to match. lhs shape= [3,3,64,128] rhs shape= [6400,1024]\n\t [[Node: save/Assign_14 = Assign[T=DT_FLOAT, _class=[\"loc:@Variable_4\"], use_locking=true, validate_shape=true, _device=\"/job:localhost/replica:0/task:0/device:GPU:0\"](Variable_4/Adam_1, save/RestoreV2/_29)]]\n\nCaused by op 'save/Assign_14', defined at:\n  File \"/opt/intel/intelpython3/lib/python3.6/runpy.py\", line 193, in _run_module_as_main\n    \"__main__\", mod_spec)\n  File \"/opt/intel/intelpython3/lib/python3.6/runpy.py\", line 85, in _run_code\n    exec(code, run_globals)\n  File \"/opt/intel/intelpython3/lib/python3.6/site-packages/ipykernel_launcher.py\", line 16, in <module>\n    app.launch_new_instance()\n  File \"/opt/intel/intelpython3/lib/python3.6/site-packages/traitlets/config/application.py\", line 658, in launch_instance\n    app.start()\n  File \"/opt/intel/intelpython3/lib/python3.6/site-packages/ipykernel/kernelapp.py\", line 497, in start\n    self.io_loop.start()\n  File \"/opt/intel/intelpython3/lib/python3.6/site-packages/tornado/platform/asyncio.py\", line 132, in start\n    self.asyncio_loop.run_forever()\n  File \"/opt/intel/intelpython3/lib/python3.6/asyncio/base_events.py\", line 421, in run_forever\n    self._run_once()\n  File \"/opt/intel/intelpython3/lib/python3.6/asyncio/base_events.py\", line 1426, in _run_once\n    handle._run()\n  File \"/opt/intel/intelpython3/lib/python3.6/asyncio/events.py\", line 127, in _run\n    self._callback(*self._args)\n  File \"/opt/intel/intelpython3/lib/python3.6/site-packages/tornado/platform/asyncio.py\", line 122, in _handle_events\n    handler_func(fileobj, events)\n  File \"/opt/intel/intelpython3/lib/python3.6/site-packages/tornado/stack_context.py\", line 300, in null_wrapper\n    return fn(*args, **kwargs)\n  File \"/opt/intel/intelpython3/lib/python3.6/site-packages/zmq/eventloop/zmqstream.py\", line 450, in _handle_events\n    self._handle_recv()\n  File \"/opt/intel/intelpython3/lib/python3.6/site-packages/zmq/eventloop/zmqstream.py\", line 480, in _handle_recv\n    self._run_callback(callback, msg)\n  File \"/opt/intel/intelpython3/lib/python3.6/site-packages/zmq/eventloop/zmqstream.py\", line 432, in _run_callback\n    callback(*args, **kwargs)\n  File \"/opt/intel/intelpython3/lib/python3.6/site-packages/tornado/stack_context.py\", line 300, in null_wrapper\n    return fn(*args, **kwargs)\n  File \"/opt/intel/intelpython3/lib/python3.6/site-packages/ipykernel/kernelbase.py\", line 283, in dispatcher\n    return self.dispatch_shell(stream, msg)\n  File \"/opt/intel/intelpython3/lib/python3.6/site-packages/ipykernel/kernelbase.py\", line 233, in dispatch_shell\n    handler(stream, idents, msg)\n  File \"/opt/intel/intelpython3/lib/python3.6/site-packages/ipykernel/kernelbase.py\", line 399, in execute_request\n    user_expressions, allow_stdin)\n  File \"/opt/intel/intelpython3/lib/python3.6/site-packages/ipykernel/ipkernel.py\", line 208, in do_execute\n    res = shell.run_cell(code, store_history=store_history, silent=silent)\n  File \"/opt/intel/intelpython3/lib/python3.6/site-packages/ipykernel/zmqshell.py\", line 537, in run_cell\n    return super(ZMQInteractiveShell, self).run_cell(*args, **kwargs)\n  File \"/opt/intel/intelpython3/lib/python3.6/site-packages/IPython/core/interactiveshell.py\", line 2662, in run_cell\n    raw_cell, store_history, silent, shell_futures)\n  File \"/opt/intel/intelpython3/lib/python3.6/site-packages/IPython/core/interactiveshell.py\", line 2785, in _run_cell\n    interactivity=interactivity, compiler=compiler, result=result)\n  File \"/opt/intel/intelpython3/lib/python3.6/site-packages/IPython/core/interactiveshell.py\", line 2901, in run_ast_nodes\n    if self.run_code(code, result):\n  File \"/opt/intel/intelpython3/lib/python3.6/site-packages/IPython/core/interactiveshell.py\", line 2961, in run_code\n    exec(code_obj, self.user_global_ns, self.user_ns)\n  File \"<ipython-input-52-279c9ac013b5>\", line 63, in <module>\n    saver = tf.train.Saver()\n  File \"/opt/intel/intelpython3/lib/python3.6/site-packages/tensorflow/python/training/saver.py\", line 1281, in __init__\n    self.build()\n  File \"/opt/intel/intelpython3/lib/python3.6/site-packages/tensorflow/python/training/saver.py\", line 1293, in build\n    self._build(self._filename, build_save=True, build_restore=True)\n  File \"/opt/intel/intelpython3/lib/python3.6/site-packages/tensorflow/python/training/saver.py\", line 1330, in _build\n    build_save=build_save, build_restore=build_restore)\n  File \"/opt/intel/intelpython3/lib/python3.6/site-packages/tensorflow/python/training/saver.py\", line 778, in _build_internal\n    restore_sequentially, reshape)\n  File \"/opt/intel/intelpython3/lib/python3.6/site-packages/tensorflow/python/training/saver.py\", line 419, in _AddRestoreOps\n    assign_ops.append(saveable.restore(saveable_tensors, shapes))\n  File \"/opt/intel/intelpython3/lib/python3.6/site-packages/tensorflow/python/training/saver.py\", line 112, in restore\n    self.op.get_shape().is_fully_defined())\n  File \"/opt/intel/intelpython3/lib/python3.6/site-packages/tensorflow/python/ops/state_ops.py\", line 216, in assign\n    validate_shape=validate_shape)\n  File \"/opt/intel/intelpython3/lib/python3.6/site-packages/tensorflow/python/ops/gen_state_ops.py\", line 60, in assign\n    use_locking=use_locking, name=name)\n  File \"/opt/intel/intelpython3/lib/python3.6/site-packages/tensorflow/python/framework/op_def_library.py\", line 787, in _apply_op_helper\n    op_def=op_def)\n  File \"/opt/intel/intelpython3/lib/python3.6/site-packages/tensorflow/python/util/deprecation.py\", line 454, in new_func\n    return func(*args, **kwargs)\n  File \"/opt/intel/intelpython3/lib/python3.6/site-packages/tensorflow/python/framework/ops.py\", line 3155, in create_op\n    op_def=op_def)\n  File \"/opt/intel/intelpython3/lib/python3.6/site-packages/tensorflow/python/framework/ops.py\", line 1717, in __init__\n    self._traceback = tf_stack.extract_stack()\n\nInvalidArgumentError (see above for traceback): Assign requires shapes of both tensors to match. lhs shape= [3,3,64,128] rhs shape= [6400,1024]\n\t [[Node: save/Assign_14 = Assign[T=DT_FLOAT, _class=[\"loc:@Variable_4\"], use_locking=true, validate_shape=true, _device=\"/job:localhost/replica:0/task:0/device:GPU:0\"](Variable_4/Adam_1, save/RestoreV2/_29)]]\n",
      "\nDuring handling of the above exception, another exception occurred:\n",
      "\u001b[0;31mInvalidArgumentError\u001b[0m                      Traceback (most recent call last)",
      "\u001b[0;32m<ipython-input-52-279c9ac013b5>\u001b[0m in \u001b[0;36m<module>\u001b[0;34m()\u001b[0m\n\u001b[1;32m     67\u001b[0m \u001b[0;32mwith\u001b[0m \u001b[0mtf\u001b[0m\u001b[0;34m.\u001b[0m\u001b[0mSession\u001b[0m\u001b[0;34m(\u001b[0m\u001b[0;34m)\u001b[0m \u001b[0;32mas\u001b[0m \u001b[0msess\u001b[0m\u001b[0;34m:\u001b[0m\u001b[0;34m\u001b[0m\u001b[0m\n\u001b[1;32m     68\u001b[0m     \u001b[0msess\u001b[0m\u001b[0;34m.\u001b[0m\u001b[0mrun\u001b[0m\u001b[0;34m(\u001b[0m\u001b[0mtf\u001b[0m\u001b[0;34m.\u001b[0m\u001b[0mglobal_variables_initializer\u001b[0m\u001b[0;34m(\u001b[0m\u001b[0;34m)\u001b[0m\u001b[0;34m)\u001b[0m\u001b[0;34m\u001b[0m\u001b[0m\n\u001b[0;32m---> 69\u001b[0;31m     \u001b[0msaver\u001b[0m\u001b[0;34m.\u001b[0m\u001b[0mrestore\u001b[0m\u001b[0;34m(\u001b[0m\u001b[0msess\u001b[0m\u001b[0;34m,\u001b[0m\u001b[0;34m\"train_model/model.ckpt\"\u001b[0m\u001b[0;34m)\u001b[0m\u001b[0;34m\u001b[0m\u001b[0m\n\u001b[0m\u001b[1;32m     70\u001b[0m \u001b[0;31m#     test_accuracy_ = sess.run(logits, feed_dict={x:batch_data})\u001b[0m\u001b[0;34m\u001b[0m\u001b[0;34m\u001b[0m\u001b[0m\n\u001b[1;32m     71\u001b[0m     \u001b[0mtest_batch_data\u001b[0m\u001b[0;34m,\u001b[0m \u001b[0mtest_batch_labels\u001b[0m \u001b[0;34m=\u001b[0m \u001b[0mload_batch_data\u001b[0m\u001b[0;34m(\u001b[0m\u001b[0mtest_data\u001b[0m\u001b[0;34m[\u001b[0m\u001b[0;34m:\u001b[0m\u001b[0;36m2000\u001b[0m\u001b[0;34m]\u001b[0m\u001b[0;34m,\u001b[0m \u001b[0mtest_label\u001b[0m\u001b[0;34m[\u001b[0m\u001b[0;34m:\u001b[0m\u001b[0;36m2000\u001b[0m\u001b[0;34m]\u001b[0m\u001b[0;34m)\u001b[0m\u001b[0;34m\u001b[0m\u001b[0m\n",
      "\u001b[0;32m/opt/intel/intelpython3/lib/python3.6/site-packages/tensorflow/python/training/saver.py\u001b[0m in \u001b[0;36mrestore\u001b[0;34m(self, sess, save_path)\u001b[0m\n\u001b[1;32m   1757\u001b[0m       \u001b[0;31m# We add a more reasonable error message here to help users (b/110263146)\u001b[0m\u001b[0;34m\u001b[0m\u001b[0;34m\u001b[0m\u001b[0m\n\u001b[1;32m   1758\u001b[0m       raise _wrap_restore_error_with_msg(\n\u001b[0;32m-> 1759\u001b[0;31m           err, \"a mismatch between the current graph and the graph\")\n\u001b[0m\u001b[1;32m   1760\u001b[0m \u001b[0;34m\u001b[0m\u001b[0m\n\u001b[1;32m   1761\u001b[0m   def _restore_from_object_based_checkpoint(self, sess, save_path,\n",
      "\u001b[0;31mInvalidArgumentError\u001b[0m: Restoring from checkpoint failed. This is most likely due to a mismatch between the current graph and the graph from the checkpoint. Please ensure that you have not altered the graph expected based on the checkpoint. Original error:\n\nAssign requires shapes of both tensors to match. lhs shape= [3,3,64,128] rhs shape= [6400,1024]\n\t [[Node: save/Assign_14 = Assign[T=DT_FLOAT, _class=[\"loc:@Variable_4\"], use_locking=true, validate_shape=true, _device=\"/job:localhost/replica:0/task:0/device:GPU:0\"](Variable_4/Adam_1, save/RestoreV2/_29)]]\n\nCaused by op 'save/Assign_14', defined at:\n  File \"/opt/intel/intelpython3/lib/python3.6/runpy.py\", line 193, in _run_module_as_main\n    \"__main__\", mod_spec)\n  File \"/opt/intel/intelpython3/lib/python3.6/runpy.py\", line 85, in _run_code\n    exec(code, run_globals)\n  File \"/opt/intel/intelpython3/lib/python3.6/site-packages/ipykernel_launcher.py\", line 16, in <module>\n    app.launch_new_instance()\n  File \"/opt/intel/intelpython3/lib/python3.6/site-packages/traitlets/config/application.py\", line 658, in launch_instance\n    app.start()\n  File \"/opt/intel/intelpython3/lib/python3.6/site-packages/ipykernel/kernelapp.py\", line 497, in start\n    self.io_loop.start()\n  File \"/opt/intel/intelpython3/lib/python3.6/site-packages/tornado/platform/asyncio.py\", line 132, in start\n    self.asyncio_loop.run_forever()\n  File \"/opt/intel/intelpython3/lib/python3.6/asyncio/base_events.py\", line 421, in run_forever\n    self._run_once()\n  File \"/opt/intel/intelpython3/lib/python3.6/asyncio/base_events.py\", line 1426, in _run_once\n    handle._run()\n  File \"/opt/intel/intelpython3/lib/python3.6/asyncio/events.py\", line 127, in _run\n    self._callback(*self._args)\n  File \"/opt/intel/intelpython3/lib/python3.6/site-packages/tornado/platform/asyncio.py\", line 122, in _handle_events\n    handler_func(fileobj, events)\n  File \"/opt/intel/intelpython3/lib/python3.6/site-packages/tornado/stack_context.py\", line 300, in null_wrapper\n    return fn(*args, **kwargs)\n  File \"/opt/intel/intelpython3/lib/python3.6/site-packages/zmq/eventloop/zmqstream.py\", line 450, in _handle_events\n    self._handle_recv()\n  File \"/opt/intel/intelpython3/lib/python3.6/site-packages/zmq/eventloop/zmqstream.py\", line 480, in _handle_recv\n    self._run_callback(callback, msg)\n  File \"/opt/intel/intelpython3/lib/python3.6/site-packages/zmq/eventloop/zmqstream.py\", line 432, in _run_callback\n    callback(*args, **kwargs)\n  File \"/opt/intel/intelpython3/lib/python3.6/site-packages/tornado/stack_context.py\", line 300, in null_wrapper\n    return fn(*args, **kwargs)\n  File \"/opt/intel/intelpython3/lib/python3.6/site-packages/ipykernel/kernelbase.py\", line 283, in dispatcher\n    return self.dispatch_shell(stream, msg)\n  File \"/opt/intel/intelpython3/lib/python3.6/site-packages/ipykernel/kernelbase.py\", line 233, in dispatch_shell\n    handler(stream, idents, msg)\n  File \"/opt/intel/intelpython3/lib/python3.6/site-packages/ipykernel/kernelbase.py\", line 399, in execute_request\n    user_expressions, allow_stdin)\n  File \"/opt/intel/intelpython3/lib/python3.6/site-packages/ipykernel/ipkernel.py\", line 208, in do_execute\n    res = shell.run_cell(code, store_history=store_history, silent=silent)\n  File \"/opt/intel/intelpython3/lib/python3.6/site-packages/ipykernel/zmqshell.py\", line 537, in run_cell\n    return super(ZMQInteractiveShell, self).run_cell(*args, **kwargs)\n  File \"/opt/intel/intelpython3/lib/python3.6/site-packages/IPython/core/interactiveshell.py\", line 2662, in run_cell\n    raw_cell, store_history, silent, shell_futures)\n  File \"/opt/intel/intelpython3/lib/python3.6/site-packages/IPython/core/interactiveshell.py\", line 2785, in _run_cell\n    interactivity=interactivity, compiler=compiler, result=result)\n  File \"/opt/intel/intelpython3/lib/python3.6/site-packages/IPython/core/interactiveshell.py\", line 2901, in run_ast_nodes\n    if self.run_code(code, result):\n  File \"/opt/intel/intelpython3/lib/python3.6/site-packages/IPython/core/interactiveshell.py\", line 2961, in run_code\n    exec(code_obj, self.user_global_ns, self.user_ns)\n  File \"<ipython-input-52-279c9ac013b5>\", line 63, in <module>\n    saver = tf.train.Saver()\n  File \"/opt/intel/intelpython3/lib/python3.6/site-packages/tensorflow/python/training/saver.py\", line 1281, in __init__\n    self.build()\n  File \"/opt/intel/intelpython3/lib/python3.6/site-packages/tensorflow/python/training/saver.py\", line 1293, in build\n    self._build(self._filename, build_save=True, build_restore=True)\n  File \"/opt/intel/intelpython3/lib/python3.6/site-packages/tensorflow/python/training/saver.py\", line 1330, in _build\n    build_save=build_save, build_restore=build_restore)\n  File \"/opt/intel/intelpython3/lib/python3.6/site-packages/tensorflow/python/training/saver.py\", line 778, in _build_internal\n    restore_sequentially, reshape)\n  File \"/opt/intel/intelpython3/lib/python3.6/site-packages/tensorflow/python/training/saver.py\", line 419, in _AddRestoreOps\n    assign_ops.append(saveable.restore(saveable_tensors, shapes))\n  File \"/opt/intel/intelpython3/lib/python3.6/site-packages/tensorflow/python/training/saver.py\", line 112, in restore\n    self.op.get_shape().is_fully_defined())\n  File \"/opt/intel/intelpython3/lib/python3.6/site-packages/tensorflow/python/ops/state_ops.py\", line 216, in assign\n    validate_shape=validate_shape)\n  File \"/opt/intel/intelpython3/lib/python3.6/site-packages/tensorflow/python/ops/gen_state_ops.py\", line 60, in assign\n    use_locking=use_locking, name=name)\n  File \"/opt/intel/intelpython3/lib/python3.6/site-packages/tensorflow/python/framework/op_def_library.py\", line 787, in _apply_op_helper\n    op_def=op_def)\n  File \"/opt/intel/intelpython3/lib/python3.6/site-packages/tensorflow/python/util/deprecation.py\", line 454, in new_func\n    return func(*args, **kwargs)\n  File \"/opt/intel/intelpython3/lib/python3.6/site-packages/tensorflow/python/framework/ops.py\", line 3155, in create_op\n    op_def=op_def)\n  File \"/opt/intel/intelpython3/lib/python3.6/site-packages/tensorflow/python/framework/ops.py\", line 1717, in __init__\n    self._traceback = tf_stack.extract_stack()\n\nInvalidArgumentError (see above for traceback): Restoring from checkpoint failed. This is most likely due to a mismatch between the current graph and the graph from the checkpoint. Please ensure that you have not altered the graph expected based on the checkpoint. Original error:\n\nAssign requires shapes of both tensors to match. lhs shape= [3,3,64,128] rhs shape= [6400,1024]\n\t [[Node: save/Assign_14 = Assign[T=DT_FLOAT, _class=[\"loc:@Variable_4\"], use_locking=true, validate_shape=true, _device=\"/job:localhost/replica:0/task:0/device:GPU:0\"](Variable_4/Adam_1, save/RestoreV2/_29)]]\n"
     ]
    }
   ],
   "source": [
    "tf.reset_default_graph()\n",
    "# saver = tf.train.import_meta_graph('train_model/model.ckpt.meta')\n",
    "\n",
    "\n",
    "with tf.Session() as sess:\n",
    "    sess.run(tf.global_variables_initializer())\n",
    "    saver.restore(sess,\"train_model/model.ckpt\")    \n",
    "#     test_accuracy_ = sess.run(logits, feed_dict={x:batch_data})\n",
    "    test_batch_data, test_batch_labels = load_batch_data(test_data[:2000], test_label[:2000])\n",
    "    feed_dict = { x: test_batch_data, y: test_batch_labels}\n",
    "    test_accuracy_ = sess.run(accuracy, feed_dict=feed_dict)\n",
    "    print('test accuracy = {}'.format(test_accuracy_))\n",
    "# sess.run(logits, feed_dict={x:batch_data}) "
   ]
  }
 ],
 "metadata": {
  "kernelspec": {
   "display_name": "Python 3",
   "language": "python",
   "name": "python3"
  },
  "language_info": {
   "codemirror_mode": {
    "name": "ipython",
    "version": 3
   },
   "file_extension": ".py",
   "mimetype": "text/x-python",
   "name": "python",
   "nbconvert_exporter": "python",
   "pygments_lexer": "ipython3",
   "version": "3.6.3"
  }
 },
 "nbformat": 4,
 "nbformat_minor": 2
}
